Workbook

Sheet Raw Responses
A1: Kano Questionnaire – Raw Responses
A2: University Course Registration System | Source: Google Form export (SRE_task.csv) | n = 40
A4: Timestamp | B4: Course search (code/title/dept) — Functional (has it) | C4: Course search (code/title/dept) — Dysfunctional (no it) | D4: Remaining seats display — Functional (has it) | E4: Remaining seats display — Dysfunctional (no it) | F4: Registration confirmation — Functional (has it) | G4: Registration confirmation — Dysfunctional (no it) | H4: SMS/email notification — Functional (has it) | I4: SMS/email notification — Dysfunctional (no it) | J4: Automatic course recommendations — Functional (has it) | K4: Automatic course recommendations — Dysfunctional (no it) | L4: Dark mode — Functional (has it) | M4: Dark mode — Dysfunctional (no it) | N4: Download timetable as PDF — Functional (has it) | O4: Download timetable as PDF — Dysfunctional (no it) | P4: Remember selected courses — Functional (has it) | Q4: Remember selected courses — Dysfunctional (no it) | R4: Data preservation (network issue) — Functional (has it) | S4: Data preservation (network issue) — Dysfunctional (no it) | T4: Fast response during peak periods — Functional (has it) | U4: Fast response during peak periods — Dysfunctional (no it)
A5: 2026/09/23 6:20:17 AM GMT+5 | B5: I like it | C5: I can tolerate it / I can live with it | D5: I like it | E5: I dislike it | F5: I expect it / It must be that way | G5: I dislike it | H5: I am neutral | I5: I am neutral | J5: I like it | K5: I can tolerate it / I can live with it | L5: I can tolerate it / I can live with it | M5: I can tolerate it / I can live with it | N5: I like it | O5: I dislike it | P5: I like it | Q5: I dislike it | R5: I dislike it | S5: I dislike it | T5: I like it | U5: I dislike it
A6: 2026/09/23 6:20:52 AM GMT+5 | B6: I am neutral | C6: I can tolerate it / I can live with it | D6: I expect it / It must be that way | E6: I dislike it | F6: I am neutral | G6: I am neutral | H6: I like it | I6: I can tolerate it / I can live with it | J6: I dislike it | K6: I am neutral | L6: I can tolerate it / I can live with it | M6: I like it | N6: I dislike it | O6: I like it | P6: I am neutral | Q6: I am neutral | R6: I expect it / It must be that way | S6: I can tolerate it / I can live with it | T6: I expect it / It must be that way | U6: I can tolerate it / I can live with it
A7: 2026/09/23 9:51:29 AM GMT+5 | B7: I am neutral | C7: I am neutral | D7: I am neutral | E7: I am neutral | F7: I am neutral | G7: I am neutral | H7: I am neutral | I7: I am neutral | J7: I am neutral | K7: I am neutral | L7: I am neutral | M7: I am neutral | N7: I am neutral | O7: I am neutral | P7: I am neutral | Q7: I am neutral | R7: I am neutral | S7: I am neutral | T7: I am neutral | U7: I am neutral
A8: 2026/09/23 12:18:56 PM GMT+5 | B8: I like it | C8: I am neutral | D8: I like it | E8: I am neutral | F8: I like it | G8: I can tolerate it / I can live with it | H8: I like it | I8: I can tolerate it / I can live with it | J8: I am neutral | K8: I am neutral | L8: I am neutral | M8: I am neutral | N8: I am neutral | O8: I am neutral | P8: I like it | Q8: I expect it / It must be that way | R8: I like it | S8: I dislike it | T8: I like it | U8: I can tolerate it / I can live with it
A9: 2026/09/23 12:20:08 PM GMT+5 | B9: I am neutral | C9: I can tolerate it / I can live with it | D9: I expect it / It must be that way | E9: I am neutral | F9: I can tolerate it / I can live with it | G9: I dislike it | H9: I can tolerate it / I can live with it | I9: I dislike it | J9: I am neutral | K9: I expect it / It must be that way | L9: I am neutral | M9: I expect it / It must be that way | N9: I like it | O9: I dislike it | P9: I expect it / It must be that way | Q9: I expect it / It must be that way | R9: I am neutral | S9: I like it | T9: I can tolerate it / I can live with it | U9: I dislike it
A10: 2026/09/23 12:26:06 PM GMT+5 | B10: I like it | C10: I expect it / It must be that way | D10: I like it | E10: I dislike it | F10: I like it | G10: I dislike it | H10: I like it | I10: I dislike it | J10: I like it | K10: I dislike it | L10: I like it | M10: I dislike it | N10: I like it | O10: I dislike it | P10: I like it | Q10: I am neutral | R10: I can tolerate it / I can live with it | S10: I can tolerate it / I can live with it | T10: I can tolerate it / I can live with it | U10: I dislike it
A11: 2026/09/23 12:27:15 PM GMT+5 | B11: I like it | C11: I dislike it | D11: I expect it / It must be that way | E11: I can tolerate it / I can live with it | F11: I am neutral | G11: I am neutral | H11: I expect it / It must be that way | I11: I dislike it | J11: I can tolerate it / I can live with it | K11: I can tolerate it / I can live with it | L11: I am neutral | M11: I can tolerate it / I can live with it | N11: I like it | O11: I expect it / It must be that way | P11: I expect it / It must be that way | Q11: I dislike it | R11: I like it | S11: I can tolerate it / I can live with it | T11: I am neutral | U11: I can tolerate it / I can live with it
A12: 2026/09/23 12:28:47 PM GMT+5 | B12: I like it | C12: I dislike it | D12: I like it | E12: I dislike it | F12: I like it | G12: I am neutral | H12: I like it | I12: I am neutral | J12: I like it | K12: I am neutral | L12: I dislike it | M12: I like it | N12: I am neutral | O12: I dislike it | Q12: I like it | R12: I like it | S12: I like it | T12: I am neutral | U12: I like it
A13: 2026/09/23 12:29:57 PM GMT+5 | B13: I like it | C13: I expect it / It must be that way | D13: I am neutral | E13: I can tolerate it / I can live with it | F13: I dislike it | G13: I like it | H13: I expect it / It must be that way | I13: I expect it / It must be that way | J13: I am neutral | K13: I expect it / It must be that way | L13: I expect it / It must be that way | M13: I expect it / It must be that way | N13: I am neutral | O13: I am neutral | P13: I expect it / It must be that way | Q13: I am neutral | R13: I am neutral | S13: I am neutral | T13: I am neutral | U13: I am neutral
A14: 2026/09/23 12:29:59 PM GMT+5 | B14: I expect it / It must be that way | C14: I am neutral | D14: I like it | E14: I like it | F14: I am neutral | G14: I can tolerate it / I can live with it | H14: I am neutral | I14: I like it | J14: I like it | K14: I expect it / It must be that way | L14: I expect it / It must be that way | M14: I like it | N14: I can tolerate it / I can live with it | O14: I dislike it | P14: I dislike it | Q14: I like it | R14: I like it | S14: I like it | T14: I expect it / It must be that way | U14: I can tolerate it / I can live with it
A15: 2026/09/23 12:32:18 PM GMT+5 | B15: I like it | C15: I dislike it | D15: I like it | E15: I dislike it | F15: I like it | G15: I dislike it | H15: I like it | I15: I dislike it | J15: I like it | K15: I dislike it | L15: I like it | M15: I can tolerate it / I can live with it | N15: I like it | O15: I dislike it | P15: I like it | Q15: I dislike it | R15: I like it | S15: I dislike it | T15: I like it | U15: I dislike it
A16: 2026/09/23 12:33:43 PM GMT+5 | B16: I like it | C16: I dislike it | D16: I like it | E16: I am neutral | F16: I expect it / It must be that way | G16: I can tolerate it / I can live with it | H16: I expect it / It must be that way | I16: I can tolerate it / I can live with it | J16: I expect it / It must be that way | K16: I dislike it | L16: I like it | M16: I can tolerate it / I can live with it | N16: I expect it / It must be that way | O16: I can tolerate it / I can live with it | P16: I like it | Q16: I can tolerate it / I can live with it | R16: I expect it / It must be that way | S16: I can tolerate it / I can live with it | T16: I like it | U16: I can tolerate it / I can live with it
A17: 2026/09/23 12:34:00 PM GMT+5 | B17: I like it | C17: I like it | D17: I like it | E17: I am neutral | F17: I dislike it | G17: I dislike it | H17: I can tolerate it / I can live with it | I17: I can tolerate it / I can live with it | J17: I am neutral | L17: I like it | M17: I dislike it | N17: I like it | O17: I like it | P17: I can tolerate it / I can live with it | Q17: I am neutral | R17: I like it | S17: I can tolerate it / I can live with it | T17: I like it | U17: I am neutral
A18: 2026/09/23 12:35:21 PM GMT+5 | B18: I like it | C18: I dislike it | D18: I expect it / It must be that way | E18: I dislike it | F18: I like it | G18: I dislike it | H18: I am neutral | I18: I am neutral | K18: I am neutral | L18: I like it | M18: I dislike it | N18: I expect it / It must be that way | O18: I can tolerate it / I can live with it | P18: I can tolerate it / I can live with it | Q18: I am neutral | R18: I like it | S18: I dislike it | T18: I like it | U18: I dislike it
A19: 2026/09/23 12:40:13 PM GMT+5 | B19: I expect it / It must be that way | C19: I dislike it | D19: I expect it / It must be that way | E19: I am neutral | F19: I like it | G19: I dislike it | H19: I like it | I19: I can tolerate it / I can live with it | J19: I expect it / It must be that way | K19: I can tolerate it / I can live with it | L19: I like it | M19: I dislike it | N19: I like it | O19: I am neutral | P19: I like it | Q19: I can tolerate it / I can live with it | R19: I am neutral | S19: I am neutral | T19: I expect it / It must be that way | U19: I can tolerate it / I can live with it
A20: 2026/09/23 12:40:58 PM GMT+5 | B20: I dislike it | C20: I dislike it | D20: I dislike it | E20: I dislike it | F20: I dislike it | G20: I dislike it | H20: I dislike it | I20: I dislike it | J20: I dislike it | K20: I dislike it | L20: I dislike it | M20: I dislike it | N20: I dislike it | O20: I dislike it | P20: I dislike it | Q20: I dislike it | R20: I dislike it | S20: I dislike it | T20: I dislike it | U20: I dislike it
A21: 2026/09/23 12:41:36 PM GMT+5 | B21: I like it | C21: I like it | D21: I like it | E21: I like it | F21: I like it | G21: I like it | H21: I like it | I21: I like it | J21: I like it | K21: I like it | L21: I like it | M21: I like it | N21: I like it | O21: I like it | P21: I like it | Q21: I like it | R21: I like it | S21: I like it | T21: I like it | U21: I like it
A22: 2026/09/23 12:45:27 PM GMT+5 | B22: I like it | C22: I dislike it | D22: I expect it / It must be that way | E22: I can tolerate it / I can live with it | F22: I am neutral | G22: I expect it / It must be that way | H22: I expect it / It must be that way | I22: I am neutral | J22: I expect it / It must be that way | K22: I can tolerate it / I can live with it | L22: I am neutral | M22: I am neutral | N22: I like it | O22: I am neutral | P22: I expect it / It must be that way | Q22: I dislike it | R22: I expect it / It must be that way | S22: I can tolerate it / I can live with it | T22: I like it | U22: I dislike it
A23: 2026/09/23 12:48:59 PM GMT+5 | B23: I expect it / It must be that way | C23: I expect it / It must be that way | D23: I can tolerate it / I can live with it | F23: I expect it / It must be that way | H23: I expect it / It must be that way | I23: I am neutral | J23: I can tolerate it / I can live with it | L23: I like it | M23: I like it | N23: I like it | P23: I am neutral | R23: I can tolerate it / I can live with it | T23: I like it | U23: I like it
A24: 2026/09/23 1:00:12 PM GMT+5 | B24: I like it | C24: I expect it / It must be that way | D24: I am neutral | E24: I expect it / It must be that way | F24: I am neutral | G24: I am neutral | I24: I expect it / It must be that way | J24: I like it | K24: I dislike it | L24: I dislike it | M24: I dislike it | N24: I dislike it | O24: I dislike it | P24: I dislike it | Q24: I can tolerate it / I can live with it | R24: I can tolerate it / I can live with it | S24: I am neutral | T24: I am neutral | U24: I expect it / It must be that way
A25: 2026/09/23 1:00:33 PM GMT+5 | B25: I like it | C25: I am neutral | D25: I like it | E25: I dislike it | F25: I like it | G25: I dislike it | H25: I dislike it | I25: I dislike it | J25: I dislike it | K25: I dislike it | L25: I dislike it | M25: I dislike it | N25: I dislike it | O25: I dislike it | P25: I dislike it | Q25: I dislike it | R25: I dislike it | S25: I dislike it | T25: I dislike it | U25: I dislike it
A26: 2026/09/23 1:02:01 PM GMT+5 | B26: I like it | C26: I dislike it | D26: I like it | E26: I dislike it | F26: I like it | G26: I dislike it | H26: I like it | I26: I dislike it | J26: I like it | K26: I dislike it | L26: I like it | M26: I dislike it | N26: I like it | O26: I dislike it | P26: I like it | Q26: I dislike it | R26: I like it | S26: I dislike it | T26: I like it | U26: I dislike it
A27: 2026/09/23 1:06:11 PM GMT+5 | B27: I like it | C27: I expect it / It must be that way | D27: I expect it / It must be that way | E27: I am neutral | F27: I expect it / It must be that way | G27: I expect it / It must be that way | H27: I am neutral | I27: I am neutral | J27: I am neutral | K27: I am neutral | L27: I can tolerate it / I can live with it | M27: I am neutral | N27: I am neutral | O27: I am neutral | P27: I like it | Q27: I can tolerate it / I can live with it | R27: I dislike it | S27: I expect it / It must be that way | T27: I like it | U27: I dislike it
A28: 2026/09/23 1:29:42 PM GMT+5 | B28: I like it | C28: I am neutral | D28: I like it | E28: I dislike it | F28: I like it | G28: I dislike it | H28: I like it | I28: I dislike it | J28: I like it | K28: I dislike it | L28: I like it | M28: I am neutral | N28: I like it | O28: I dislike it | P28: I like it | Q28: I dislike it | R28: I am neutral | T28: I like it | U28: I dislike it
A29: 2026/09/23 1:29:46 PM GMT+5 | B29: I expect it / It must be that way | C29: I can tolerate it / I can live with it | D29: I like it | E29: I can tolerate it / I can live with it | F29: I am neutral | G29: I am neutral | H29: I expect it / It must be that way | I29: I can tolerate it / I can live with it | J29: I can tolerate it / I can live with it | K29: I can tolerate it / I can live with it | L29: I am neutral | M29: I am neutral | N29: I like it | O29: I dislike it | P29: I expect it / It must be that way | Q29: I am neutral | R29: I expect it / It must be that way | S29: I dislike it | T29: I expect it / It must be that way | U29: I dislike it
A30: 2026/09/23 1:47:39 PM GMT+5 | B30: I expect it / It must be that way | C30: I can tolerate it / I can live with it | D30: I expect it / It must be that way | E30: I can tolerate it / I can live with it | F30: I like it | G30: I dislike it | H30: I like it | I30: I dislike it | J30: I am neutral | K30: I am neutral | L30: I expect it / It must be that way | M30: I dislike it | N30: I like it | O30: I dislike it | P30: I expect it / It must be that way | Q30: I can tolerate it / I can live with it | R30: I like it | S30: I am neutral | T30: I expect it / It must be that way | U30: I am neutral
A31: 2026/09/23 1:49:18 PM GMT+5 | B31: I expect it / It must be that way | C31: I am neutral | D31: I like it | E31: I expect it / It must be that way | F31: I like it | G31: I dislike it | H31: I like it | I31: I can tolerate it / I can live with it | J31: I like it | K31: I can tolerate it / I can live with it | L31: I like it | M31: I dislike it | N31: I expect it / It must be that way | O31: I dislike it | P31: I expect it / It must be that way | Q31: I can tolerate it / I can live with it | R31: I like it | S31: I dislike it | T31: I like it | U31: I can tolerate it / I can live with it
A32: 2026/09/23 1:57:38 PM GMT+5 | B32: I dislike it | C32: I dislike it | D32: I dislike it | E32: I dislike it | F32: I dislike it | G32: I dislike it | H32: I dislike it | I32: I dislike it | J32: I dislike it | K32: I dislike it | L32: I dislike it | M32: I dislike it | N32: I dislike it | O32: I dislike it | P32: I dislike it | Q32: I dislike it | R32: I dislike it | S32: I dislike it | T32: I dislike it | U32: I dislike it
A33: 2026/09/23 2:04:18 PM GMT+5 | B33: I like it | C33: I am neutral | D33: I like it | E33: I can tolerate it / I can live with it | F33: I like it | G33: I expect it / It must be that way | H33: I like it | I33: I expect it / It must be that way | J33: I am neutral | K33: I am neutral | L33: I dislike it | M33: I expect it / It must be that way | N33: I like it | O33: I am neutral | P33: I like it | Q33: I can tolerate it / I can live with it | R33: I dislike it | S33: I dislike it | T33: I like it | U33: I can tolerate it / I can live with it
A34: 2026/09/23 2:08:17 PM GMT+5 | B34: I like it | C34: I am neutral | D34: I like it | E34: I am neutral | F34: I like it | G34: I can tolerate it / I can live with it | H34: I expect it / It must be that way | I34: I am neutral | J34: I dislike it | K34: I am neutral | L34: I dislike it | M34: I like it | N34: I like it | O34: I am neutral | P34: I like it | Q34: I can tolerate it / I can live with it | R34: I like it | S34: I am neutral | T34: I like it | U34: I can tolerate it / I can live with it
A35: 2026/09/23 2:10:51 PM GMT+5 | B35: I like it | C35: I can tolerate it / I can live with it | D35: I expect it / It must be that way | E35: I dislike it | F35: I dislike it | G35: I am neutral | H35: I like it | I35: I am neutral | J35: I expect it / It must be that way | K35: I can tolerate it / I can live with it | L35: I like it | M35: I can tolerate it / I can live with it | N35: I like it | O35: I am neutral | P35: I am neutral | Q35: I dislike it | R35: I am neutral | S35: I am neutral | T35: I am neutral | U35: I am neutral
A36: 2026/09/23 2:13:54 PM GMT+5 | B36: I like it | C36: I am neutral | D36: I like it | E36: I am neutral | F36: I like it | G36: I dislike it | H36: I like it | I36: I can tolerate it / I can live with it | J36: I like it | K36: I can tolerate it / I can live with it | L36: I like it | M36: I can tolerate it / I can live with it | N36: I can tolerate it / I can live with it | O36: I can tolerate it / I can live with it | P36: I dislike it | Q36: I like it | R36: I dislike it | S36: I like it | T36: I like it | U36: I dislike it
A37: 2026/09/23 2:22:20 PM GMT+5 | B37: I like it | C37: I dislike it | D37: I like it | E37: I can tolerate it / I can live with it | F37: I like it | G37: I dislike it | H37: I like it | I37: I dislike it | J37: I like it | K37: I dislike it | L37: I am neutral | M37: I am neutral | N37: I like it | O37: I can tolerate it / I can live with it | P37: I like it | Q37: I can tolerate it / I can live with it | R37: I like it | S37: I dislike it | T37: I like it | U37: I dislike it
A38: 2026/09/23 2:27:07 PM GMT+5
A39: 2026/09/23 3:02:41 PM GMT+5 | B39: I like it | C39: I dislike it | D39: I like it | E39: I am neutral | F39: I like it | G39: I can tolerate it / I can live with it | H39: I like it | I39: I am neutral | J39: I like it | K39: I am neutral | L39: I like it | M39: I am neutral | N39: I like it | O39: I dislike it | P39: I like it | Q39: I am neutral | R39: I like it | S39: I am neutral | T39: I like it | U39: I am neutral
A40: 2026/09/23 3:09:58 PM GMT+5 | B40: I like it | C40: I dislike it | D40: I expect it / It must be that way | E40: I dislike it | F40: I expect it / It must be that way | G40: I dislike it | H40: I like it | I40: I dislike it | J40: I like it | K40: I can tolerate it / I can live with it | L40: I am neutral | M40: I am neutral | N40: I expect it / It must be that way | O40: I dislike it | P40: I like it | Q40: I dislike it | R40: I expect it / It must be that way | S40: I dislike it | T40: I expect it / It must be that way | U40: I dislike it
A41: 2026/09/23 3:37:41 PM GMT+5 | B41: I like it | C41: I can tolerate it / I can live with it | D41: I like it | E41: I can tolerate it / I can live with it | F41: I expect it / It must be that way | G41: I expect it / It must be that way | H41: I expect it / It must be that way | I41: I can tolerate it / I can live with it | J41: I dislike it | K41: I expect it / It must be that way | L41: I like it | M41: I dislike it | N41: I like it | O41: I dislike it | P41: I like it | Q41: I dislike it | R41: I expect it / It must be that way | S41: I can tolerate it / I can live with it | T41: I like it | U41: I dislike it
...

Sheet Kano Matrix
A1: Kano Evaluation Matrix
A2: Standard classification logic used by the Classification sheet's formulas.
A4: Functional \ Dysfunctional | B4: I like it | C4: I expect it / It must be that way | D4: I am neutral | E4: I can tolerate it / I can live with it | F4: I dislike it
A5: I like it | B5: Q | C5: A | D5: A | E5: A | F5: O
A6: I expect it / It must be that way | B6: R | C6: I | D6: I | E6: I | F6: M
A7: I am neutral | B7: R | C7: I | D7: I | E7: I | F7: M
A8: I can tolerate it / I can live with it | B8: R | C8: I | D8: I | E8: I | F8: M
A9: I dislike it | B9: R | C9: R | D9: R | E9: R | F9: Q
A11: Legend: M = Must-be | O = One-dimensional | A = Attractive | I = Indifferent | R = Reverse | Q = Questionable

Sheet Classification
A1: Per-Respondent Kano Classification
A2: Each cell below looks up the functional/dysfunctional answer pair on 'Raw Responses' against the 'Kano Matrix'.
A4: Timestamp | B4: Course search (code/title/dept) | C4: Remaining seats display | D4: Registration confirmation | E4: SMS/email notification | F4: Automatic course recommendations | G4: Dark mode | H4: Download timetable as PDF | I4: Remember selected courses | J4: Data preservation (network issue) | K4: Fast response during peak periods
A5: ='Raw Responses'!A5 -> 2026/09/23 6:20:17 AM GMT+5 | B5: =IF(OR('Raw Responses'!B5="",'Raw Responses'!C5=""),"Incomplete",IFERROR(INDEX('Kano Matrix'!$B$5:$F$9,MATCH('Raw Responses'!B5,'Kano Matrix'!$A$5:$A$9,0),MATCH('Raw Responses'!C5,'Kano Matrix'!$B$4:$F$4,0)),"Incomplete")) -> A | C5: =IF(OR('Raw Responses'!D5="",'Raw Responses'!E5=""),"Incomplete",IFERROR(INDEX('Kano Matrix'!$B$5:$F$9,MATCH('Raw Responses'!D5,'Kano Matrix'!$A$5:$A$9,0),MATCH('Raw Responses'!E5,'Kano Matrix'!$B$4:$F$4,0)),"Incomplete")) -> O | D5: =IF(OR('Raw Responses'!F5="",'Raw Responses'!G5=""),"Incomplete",IFERROR(INDEX('Kano Matrix'!$B$5:$F$9,MATCH('Raw Responses'!F5,'Kano Matrix'!$A$5:$A$9,0),MATCH('Raw Responses'!G5,'Kano Matrix'!$B$4:$F$4,0)),"Incomplete")) -> M | E5: =IF(OR('Raw Responses'!H5="",'Raw Responses'!I5=""),"Incomplete",IFERROR(INDEX('Kano Matrix'!$B$5:$F$9,MATCH('Raw Responses'!H5,'Kano Matrix'!$A$5:$A$9,0),MATCH('Raw Responses'!I5,'Kano Matrix'!$B$4:$F$4,0)),"Incomplete")) -> I | F5: =IF(OR('Raw Responses'!J5="",'Raw Responses'!K5=""),"Incomplete",IFERROR(INDEX('Kano Matrix'!$B$5:$F$9,MATCH('Raw Responses'!J5,'Kano Matrix'!$A$5:$A$9,0),MATCH('Raw Responses'!K5,'Kano Matrix'!$B$4:$F$4,0)),"Incomplete")) -> A | G5: =IF(OR('Raw Responses'!L5="",'Raw Responses'!M5=""),"Incomplete",IFERROR(INDEX('Kano Matrix'!$B$5:$F$9,MATCH('Raw Responses'!L5,'Kano Matrix'!$A$5:$A$9,0),MATCH('Raw Responses'!M5,'Kano Matrix'!$B$4:$F$4,0)),"Incomplete")) -> I | H5: =IF(OR('Raw Responses'!N5="",'Raw Responses'!O5=""),"Incomplete",IFERROR(INDEX('Kano Matrix'!$B$5:$F$9,MATCH('Raw Responses'!N5,'Kano Matrix'!$A$5:$A$9,0),MATCH('Raw Responses'!O5,'Kano Matrix'!$B$4:$F$4,0)),"Incomplete")) -> O | I5: =IF(OR('Raw Responses'!P5="",'Raw Responses'!Q5=""),"Incomplete",IFERROR(INDEX('Kano Matrix'!$B$5:$F$9,MATCH('Raw Responses'!P5,'Kano Matrix'!$A$5:$A$9,0),MATCH('Raw Responses'!Q5,'Kano Matrix'!$B$4:$F$4,0)),"Incomplete")) -> O | J5: =IF(OR('Raw Responses'!R5="",'Raw Responses'!S5=""),"Incomplete",IFERROR(INDEX('Kano Matrix'!$B$5:$F$9,MATCH('Raw Responses'!R5,'Kano Matrix'!$A$5:$A$9,0),MATCH('Raw Responses'!S5,'Kano Matrix'!$B$4:$F$4,0)),"Incomplete")) -> Q | K5: =IF(OR('Raw Responses'!T5="",'Raw Responses'!U5=""),"Incomplete",IFERROR(INDEX('Kano Matrix'!$B$5:$F$9,MATCH('Raw Responses'!T5,'Kano Matrix'!$A$5:$A$9,0),MATCH('Raw Responses'!U5,'Kano Matrix'!$B$4:$F$4,0)),"Incomplete")) -> O
A6: ='Raw Responses'!A6 -> 2026/09/23 6:20:52 AM GMT+5 | B6: =IF(OR('Raw Responses'!B6="",'Raw Responses'!C6=""),"Incomplete",IFERROR(INDEX('Kano Matrix'!$B$5:$F$9,MATCH('Raw Responses'!B6,'Kano Matrix'!$A$5:$A$9,0),MATCH('Raw Responses'!C6,'Kano Matrix'!$B$4:$F$4,0)),"Incomplete")) -> I | C6: =IF(OR('Raw Responses'!D6="",'Raw Responses'!E6=""),"Incomplete",IFERROR(INDEX('Kano Matrix'!$B$5:$F$9,MATCH('Raw Responses'!D6,'Kano Matrix'!$A$5:$A$9,0),MATCH('Raw Responses'!E6,'Kano Matrix'!$B$4:$F$4,0)),"Incomplete")) -> M | D6: =IF(OR('Raw Responses'!F6="",'Raw Responses'!G6=""),"Incomplete",IFERROR(INDEX('Kano Matrix'!$B$5:$F$9,MATCH('Raw Responses'!F6,'Kano Matrix'!$A$5:$A$9,0),MATCH('Raw Responses'!G6,'Kano Matrix'!$B$4:$F$4,0)),"Incomplete")) -> I | E6: =IF(OR('Raw Responses'!H6="",'Raw Responses'!I6=""),"Incomplete",IFERROR(INDEX('Kano Matrix'!$B$5:$F$9,MATCH('Raw Responses'!H6,'Kano Matrix'!$A$5:$A$9,0),MATCH('Raw Responses'!I6,'Kano Matrix'!$B$4:$F$4,0)),"Incomplete")) -> A | F6: =IF(OR('Raw Responses'!J6="",'Raw Responses'!K6=""),"Incomplete",IFERROR(INDEX('Kano Matrix'!$B$5:$F$9,MATCH('Raw Responses'!J6,'Kano Matrix'!$A$5:$A$9,0),MATCH('Raw Responses'!K6,'Kano Matrix'!$B$4:$F$4,0)),"Incomplete")) -> R | G6: =IF(OR('Raw Responses'!L6="",'Raw Responses'!M6=""),"Incomplete",IFERROR(INDEX('Kano Matrix'!$B$5:$F$9,MATCH('Raw Responses'!L6,'Kano Matrix'!$A$5:$A$9,0),MATCH('Raw Responses'!M6,'Kano Matrix'!$B$4:$F$4,0)),"Incomplete")) -> R | H6: =IF(OR('Raw Responses'!N6="",'Raw Responses'!O6=""),"Incomplete",IFERROR(INDEX('Kano Matrix'!$B$5:$F$9,MATCH('Raw Responses'!N6,'Kano Matrix'!$A$5:$A$9,0),MATCH('Raw Responses'!O6,'Kano Matrix'!$B$4:$F$4,0)),"Incomplete")) -> R | I6: =IF(OR('Raw Responses'!P6="",'Raw Responses'!Q6=""),"Incomplete",IFERROR(INDEX('Kano Matrix'!$B$5:$F$9,MATCH('Raw Responses'!P6,'Kano Matrix'!$A$5:$A$9,0),MATCH('Raw Responses'!Q6,'Kano Matrix'!$B$4:$F$4,0)),"Incomplete")) -> I | J6: =IF(OR('Raw Responses'!R6="",'Raw Responses'!S6=""),"Incomplete",IFERROR(INDEX('Kano Matrix'!$B$5:$F$9,MATCH('Raw Responses'!R6,'Kano Matrix'!$A$5:$A$9,0),MATCH('Raw Responses'!S6,'Kano Matrix'!$B$4:$F$4,0)),"Incomplete")) -> I | K6: =IF(OR('Raw Responses'!T6="",'Raw Responses'!U6=""),"Incomplete",IFERROR(INDEX('Kano Matrix'!$B$5:$F$9,MATCH('Raw Responses'!T6,'Kano Matrix'!$A$5:$A$9,0),MATCH('Raw Responses'!U6,'Kano Matrix'!$B$4:$F$4,0)),"Incomplete")) -> I
A7: ='Raw Responses'!A7 -> 2026/09/23 9:51:29 AM GMT+5 | B7: =IF(OR('Raw Responses'!B7="",'Raw Responses'!C7=""),"Incomplete",IFERROR(INDEX('Kano Matrix'!$B$5:$F$9,MATCH('Raw Responses'!B7,'Kano Matrix'!$A$5:$A$9,0),MATCH('Raw Responses'!C7,'Kano Matrix'!$B$4:$F$4,0)),"Incomplete")) -> I | C7: =IF(OR('Raw Responses'!D7="",'Raw Responses'!E7=""),"Incomplete",IFERROR(INDEX('Kano Matrix'!$B$5:$F$9,MATCH('Raw Responses'!D7,'Kano Matrix'!$A$5:$A$9,0),MATCH('Raw Responses'!E7,'Kano Matrix'!$B$4:$F$4,0)),"Incomplete")) -> I | D7: =IF(OR('Raw Responses'!F7="",'Raw Responses'!G7=""),"Incomplete",IFERROR(INDEX('Kano Matrix'!$B$5:$F$9,MATCH('Raw Responses'!F7,'Kano Matrix'!$A$5:$A$9,0),MATCH('Raw Responses'!G7,'Kano Matrix'!$B$4:$F$4,0)),"Incomplete")) -> I | E7: =IF(OR('Raw Responses'!H7="",'Raw Responses'!I7=""),"Incomplete",IFERROR(INDEX('Kano Matrix'!$B$5:$F$9,MATCH('Raw Responses'!H7,'Kano Matrix'!$A$5:$A$9,0),MATCH('Raw Responses'!I7,'Kano Matrix'!$B$4:$F$4,0)),"Incomplete")) -> I | F7: =IF(OR('Raw Responses'!J7="",'Raw Responses'!K7=""),"Incomplete",IFERROR(INDEX('Kano Matrix'!$B$5:$F$9,MATCH('Raw Responses'!J7,'Kano Matrix'!$A$5:$A$9,0),MATCH('Raw Responses'!K7,'Kano Matrix'!$B$4:$F$4,0)),"Incomplete")) -> I | G7: =IF(OR('Raw Responses'!L7="",'Raw Responses'!M7=""),"Incomplete",IFERROR(INDEX('Kano Matrix'!$B$5:$F$9,MATCH('Raw Responses'!L7,'Kano Matrix'!$A$5:$A$9,0),MATCH('Raw Responses'!M7,'Kano Matrix'!$B$4:$F$4,0)),"Incomplete")) -> I | H7: =IF(OR('Raw Responses'!N7="",'Raw Responses'!O7=""),"Incomplete",IFERROR(INDEX('Kano Matrix'!$B$5:$F$9,MATCH('Raw Responses'!N7,'Kano Matrix'!$A$5:$A$9,0),MATCH('Raw Responses'!O7,'Kano Matrix'!$B$4:$F$4,0)),"Incomplete")) -> I | I7: =IF(OR('Raw Responses'!P7="",'Raw Responses'!Q7=""),"Incomplete",IFERROR(INDEX('Kano Matrix'!$B$5:$F$9,MATCH('Raw Responses'!P7,'Kano Matrix'!$A$5:$A$9,0),MATCH('Raw Responses'!Q7,'Kano Matrix'!$B$4:$F$4,0)),"Incomplete")) -> I | J7: =IF(OR('Raw Responses'!R7="",'Raw Responses'!S7=""),"Incomplete",IFERROR(INDEX('Kano Matrix'!$B$5:$F$9,MATCH('Raw Responses'!R7,'Kano Matrix'!$A$5:$A$9,0),MATCH('Raw Responses'!S7,'Kano Matrix'!$B$4:$F$4,0)),"Incomplete")) -> I | K7: =IF(OR('Raw Responses'!T7="",'Raw Responses'!U7=""),"Incomplete",IFERROR(INDEX('Kano Matrix'!$B$5:$F$9,MATCH('Raw Responses'!T7,'Kano Matrix'!$A$5:$A$9,0),MATCH('Raw Responses'!U7,'Kano Matrix'!$B$4:$F$4,0)),"Incomplete")) -> I
A8: ='Raw Responses'!A8 -> 2026/09/23 12:18:56 PM GMT+5 | B8: =IF(OR('Raw Responses'!B8="",'Raw Responses'!C8=""),"Incomplete",IFERROR(INDEX('Kano Matrix'!$B$5:$F$9,MATCH('Raw Responses'!B8,'Kano Matrix'!$A$5:$A$9,0),MATCH('Raw Responses'!C8,'Kano Matrix'!$B$4:$F$4,0)),"Incomplete")) -> A | C8: =IF(OR('Raw Responses'!D8="",'Raw Responses'!E8=""),"Incomplete",IFERROR(INDEX('Kano Matrix'!$B$5:$F$9,MATCH('Raw Responses'!D8,'Kano Matrix'!$A$5:$A$9,0),MATCH('Raw Responses'!E8,'Kano Matrix'!$B$4:$F$4,0)),"Incomplete")) -> A | D8: =IF(OR('Raw Responses'!F8="",'Raw Responses'!G8=""),"Incomplete",IFERROR(INDEX('Kano Matrix'!$B$5:$F$9,MATCH('Raw Responses'!F8,'Kano Matrix'!$A$5:$A$9,0),MATCH('Raw Responses'!G8,'Kano Matrix'!$B$4:$F$4,0)),"Incomplete")) -> A | E8: =IF(OR('Raw Responses'!H8="",'Raw Responses'!I8=""),"Incomplete",IFERROR(INDEX('Kano Matrix'!$B$5:$F$9,MATCH('Raw Responses'!H8,'Kano Matrix'!$A$5:$A$9,0),MATCH('Raw Responses'!I8,'Kano Matrix'!$B$4:$F$4,0)),"Incomplete")) -> A | F8: =IF(OR('Raw Responses'!J8="",'Raw Responses'!K8=""),"Incomplete",IFERROR(INDEX('Kano Matrix'!$B$5:$F$9,MATCH('Raw Responses'!J8,'Kano Matrix'!$A$5:$A$9,0),MATCH('Raw Responses'!K8,'Kano Matrix'!$B$4:$F$4,0)),"Incomplete")) -> I | G8: =IF(OR('Raw Responses'!L8="",'Raw Responses'!M8=""),"Incomplete",IFERROR(INDEX('Kano Matrix'!$B$5:$F$9,MATCH('Raw Responses'!L8,'Kano Matrix'!$A$5:$A$9,0),MATCH('Raw Responses'!M8,'Kano Matrix'!$B$4:$F$4,0)),"Incomplete")) -> I | H8: =IF(OR('Raw Responses'!N8="",'Raw Responses'!O8=""),"Incomplete",IFERROR(INDEX('Kano Matrix'!$B$5:$F$9,MATCH('Raw Responses'!N8,'Kano Matrix'!$A$5:$A$9,0),MATCH('Raw Responses'!O8,'Kano Matrix'!$B$4:$F$4,0)),"Incomplete")) -> I | I8: =IF(OR('Raw Responses'!P8="",'Raw Responses'!Q8=""),"Incomplete",IFERROR(INDEX('Kano Matrix'!$B$5:$F$9,MATCH('Raw Responses'!P8,'Kano Matrix'!$A$5:$A$9,0),MATCH('Raw Responses'!Q8,'Kano Matrix'!$B$4:$F$4,0)),"Incomplete")) -> A | J8: =IF(OR('Raw Responses'!R8="",'Raw Responses'!S8=""),"Incomplete",IFERROR(INDEX('Kano Matrix'!$B$5:$F$9,MATCH('Raw Responses'!R8,'Kano Matrix'!$A$5:$A$9,0),MATCH('Raw Responses'!S8,'Kano Matrix'!$B$4:$F$4,0)),"Incomplete")) -> O | K8: =IF(OR('Raw Responses'!T8="",'Raw Responses'!U8=""),"Incomplete",IFERROR(INDEX('Kano Matrix'!$B$5:$F$9,MATCH('Raw Responses'!T8,'Kano Matrix'!$A$5:$A$9,0),MATCH('Raw Responses'!U8,'Kano Matrix'!$B$4:$F$4,0)),"Incomplete")) -> A
A9: ='Raw Responses'!A9 -> 2026/09/23 12:20:08 PM GMT+5 | B9: =IF(OR('Raw Responses'!B9="",'Raw Responses'!C9=""),"Incomplete",IFERROR(INDEX('Kano Matrix'!$B$5:$F$9,MATCH('Raw Responses'!B9,'Kano Matrix'!$A$5:$A$9,0),MATCH('Raw Responses'!C9,'Kano Matrix'!$B$4:$F$4,0)),"Incomplete")) -> I | C9: =IF(OR('Raw Responses'!D9="",'Raw Responses'!E9=""),"Incomplete",IFERROR(INDEX('Kano Matrix'!$B$5:$F$9,MATCH('Raw Responses'!D9,'Kano Matrix'!$A$5:$A$9,0),MATCH('Raw Responses'!E9,'Kano Matrix'!$B$4:$F$4,0)),"Incomplete")) -> I | D9: =IF(OR('Raw Responses'!F9="",'Raw Responses'!G9=""),"Incomplete",IFERROR(INDEX('Kano Matrix'!$B$5:$F$9,MATCH('Raw Responses'!F9,'Kano Matrix'!$A$5:$A$9,0),MATCH('Raw Responses'!G9,'Kano Matrix'!$B$4:$F$4,0)),"Incomplete")) -> M | E9: =IF(OR('Raw Responses'!H9="",'Raw Responses'!I9=""),"Incomplete",IFERROR(INDEX('Kano Matrix'!$B$5:$F$9,MATCH('Raw Responses'!H9,'Kano Matrix'!$A$5:$A$9,0),MATCH('Raw Responses'!I9,'Kano Matrix'!$B$4:$F$4,0)),"Incomplete")) -> M | F9: =IF(OR('Raw Responses'!J9="",'Raw Responses'!K9=""),"Incomplete",IFERROR(INDEX('Kano Matrix'!$B$5:$F$9,MATCH('Raw Responses'!J9,'Kano Matrix'!$A$5:$A$9,0),MATCH('Raw Responses'!K9,'Kano Matrix'!$B$4:$F$4,0)),"Incomplete")) -> I | G9: =IF(OR('Raw Responses'!L9="",'Raw Responses'!M9=""),"Incomplete",IFERROR(INDEX('Kano Matrix'!$B$5:$F$9,MATCH('Raw Responses'!L9,'Kano Matrix'!$A$5:$A$9,0),MATCH('Raw Responses'!M9,'Kano Matrix'!$B$4:$F$4,0)),"Incomplete")) -> I | H9: =IF(OR('Raw Responses'!N9="",'Raw Responses'!O9=""),"Incomplete",IFERROR(INDEX('Kano Matrix'!$B$5:$F$9,MATCH('Raw Responses'!N9,'Kano Matrix'!$A$5:$A$9,0),MATCH('Raw Responses'!O9,'Kano Matrix'!$B$4:$F$4,0)),"Incomplete")) -> O | I9: =IF(OR('Raw Responses'!P9="",'Raw Responses'!Q9=""),"Incomplete",IFERROR(INDEX('Kano Matrix'!$B$5:$F$9,MATCH('Raw Responses'!P9,'Kano Matrix'!$A$5:$A$9,0),MATCH('Raw Responses'!Q9,'Kano Matrix'!$B$4:$F$4,0)),"Incomplete")) -> I | J9: =IF(OR('Raw Responses'!R9="",'Raw Responses'!S9=""),"Incomplete",IFERROR(INDEX('Kano Matrix'!$B$5:$F$9,MATCH('Raw Responses'!R9,'Kano Matrix'!$A$5:$A$9,0),MATCH('Raw Responses'!S9,'Kano Matrix'!$B$4:$F$4,0)),"Incomplete")) -> R | K9: =IF(OR('Raw Responses'!T9="",'Raw Responses'!U9=""),"Incomplete",IFERROR(INDEX('Kano Matrix'!$B$5:$F$9,MATCH('Raw Responses'!T9,'Kano Matrix'!$A$5:$A$9,0),MATCH('Raw Responses'!U9,'Kano Matrix'!$B$4:$F$4,0)),"Incomplete")) -> M
A10: ='Raw Responses'!A10 -> 2026/09/23 12:26:06 PM GMT+5 | B10: =IF(OR('Raw Responses'!B10="",'Raw Responses'!C10=""),"Incomplete",IFERROR(INDEX('Kano Matrix'!$B$5:$F$9,MATCH('Raw Responses'!B10,'Kano Matrix'!$A$5:$A$9,0),MATCH('Raw Responses'!C10,'Kano Matrix'!$B$4:$F$4,0)),"Incomplete")) -> A | C10: =IF(OR('Raw Responses'!D10="",'Raw Responses'!E10=""),"Incomplete",IFERROR(INDEX('Kano Matrix'!$B$5:$F$9,MATCH('Raw Responses'!D10,'Kano Matrix'!$A$5:$A$9,0),MATCH('Raw Responses'!E10,'Kano Matrix'!$B$4:$F$4,0)),"Incomplete")) -> O | D10: =IF(OR('Raw Responses'!F10="",'Raw Responses'!G10=""),"Incomplete",IFERROR(INDEX('Kano Matrix'!$B$5:$F$9,MATCH('Raw Responses'!F10,'Kano Matrix'!$A$5:$A$9,0),MATCH('Raw Responses'!G10,'Kano Matrix'!$B$4:$F$4,0)),"Incomplete")) -> O | E10: =IF(OR('Raw Responses'!H10="",'Raw Responses'!I10=""),"Incomplete",IFERROR(INDEX('Kano Matrix'!$B$5:$F$9,MATCH('Raw Responses'!H10,'Kano Matrix'!$A$5:$A$9,0),MATCH('Raw Responses'!I10,'Kano Matrix'!$B$4:$F$4,0)),"Incomplete")) -> O | F10: =IF(OR('Raw Responses'!J10="",'Raw Responses'!K10=""),"Incomplete",IFERROR(INDEX('Kano Matrix'!$B$5:$F$9,MATCH('Raw Responses'!J10,'Kano Matrix'!$A$5:$A$9,0),MATCH('Raw Responses'!K10,'Kano Matrix'!$B$4:$F$4,0)),"Incomplete")) -> O | G10: =IF(OR('Raw Responses'!L10="",'Raw Responses'!M10=""),"Incomplete",IFERROR(INDEX('Kano Matrix'!$B$5:$F$9,MATCH('Raw Responses'!L10,'Kano Matrix'!$A$5:$A$9,0),MATCH('Raw Responses'!M10,'Kano Matrix'!$B$4:$F$4,0)),"Incomplete")) -> O | H10: =IF(OR('Raw Responses'!N10="",'Raw Responses'!O10=""),"Incomplete",IFERROR(INDEX('Kano Matrix'!$B$5:$F$9,MATCH('Raw Responses'!N10,'Kano Matrix'!$A$5:$A$9,0),MATCH('Raw Responses'!O10,'Kano Matrix'!$B$4:$F$4,0)),"Incomplete")) -> O | I10: =IF(OR('Raw Responses'!P10="",'Raw Responses'!Q10=""),"Incomplete",IFERROR(INDEX('Kano Matrix'!$B$5:$F$9,MATCH('Raw Responses'!P10,'Kano Matrix'!$A$5:$A$9,0),MATCH('Raw Responses'!Q10,'Kano Matrix'!$B$4:$F$4,0)),"Incomplete")) -> A | J10: =IF(OR('Raw Responses'!R10="",'Raw Responses'!S10=""),"Incomplete",IFERROR(INDEX('Kano Matrix'!$B$5:$F$9,MATCH('Raw Responses'!R10,'Kano Matrix'!$A$5:$A$9,0),MATCH('Raw Responses'!S10,'Kano Matrix'!$B$4:$F$4,0)),"Incomplete")) -> I | K10: =IF(OR('Raw Responses'!T10="",'Raw Responses'!U10=""),"Incomplete",IFERROR(INDEX('Kano Matrix'!$B$5:$F$9,MATCH('Raw Responses'!T10,'Kano Matrix'!$A$5:$A$9,0),MATCH('Raw Responses'!U10,'Kano Matrix'!$B$4:$F$4,0)),"Incomplete")) -> M
A11: ='Raw Responses'!A11 -> 2026/09/23 12:27:15 PM GMT+5 | B11: =IF(OR('Raw Responses'!B11="",'Raw Responses'!C11=""),"Incomplete",IFERROR(INDEX('Kano Matrix'!$B$5:$F$9,MATCH('Raw Responses'!B11,'Kano Matrix'!$A$5:$A$9,0),MATCH('Raw Responses'!C11,'Kano Matrix'!$B$4:$F$4,0)),"Incomplete")) -> O | C11: =IF(OR('Raw Responses'!D11="",'Raw Responses'!E11=""),"Incomplete",IFERROR(INDEX('Kano Matrix'!$B$5:$F$9,MATCH('Raw Responses'!D11,'Kano Matrix'!$A$5:$A$9,0),MATCH('Raw Responses'!E11,'Kano Matrix'!$B$4:$F$4,0)),"Incomplete")) -> I | D11: =IF(OR('Raw Responses'!F11="",'Raw Responses'!G11=""),"Incomplete",IFERROR(INDEX('Kano Matrix'!$B$5:$F$9,MATCH('Raw Responses'!F11,'Kano Matrix'!$A$5:$A$9,0),MATCH('Raw Responses'!G11,'Kano Matrix'!$B$4:$F$4,0)),"Incomplete")) -> I | E11: =IF(OR('Raw Responses'!H11="",'Raw Responses'!I11=""),"Incomplete",IFERROR(INDEX('Kano Matrix'!$B$5:$F$9,MATCH('Raw Responses'!H11,'Kano Matrix'!$A$5:$A$9,0),MATCH('Raw Responses'!I11,'Kano Matrix'!$B$4:$F$4,0)),"Incomplete")) -> M | F11: =IF(OR('Raw Responses'!J11="",'Raw Responses'!K11=""),"Incomplete",IFERROR(INDEX('Kano Matrix'!$B$5:$F$9,MATCH('Raw Responses'!J11,'Kano Matrix'!$A$5:$A$9,0),MATCH('Raw Responses'!K11,'Kano Matrix'!$B$4:$F$4,0)),"Incomplete")) -> I | G11: =IF(OR('Raw Responses'!L11="",'Raw Responses'!M11=""),"Incomplete",IFERROR(INDEX('Kano Matrix'!$B$5:$F$9,MATCH('Raw Responses'!L11,'Kano Matrix'!$A$5:$A$9,0),MATCH('Raw Responses'!M11,'Kano Matrix'!$B$4:$F$4,0)),"Incomplete")) -> I | H11: =IF(OR('Raw Responses'!N11="",'Raw Responses'!O11=""),"Incomplete",IFERROR(INDEX('Kano Matrix'!$B$5:$F$9,MATCH('Raw Responses'!N11,'Kano Matrix'!$A$5:$A$9,0),MATCH('Raw Responses'!O11,'Kano Matrix'!$B$4:$F$4,0)),"Incomplete")) -> A | I11: =IF(OR('Raw Responses'!P11="",'Raw Responses'!Q11=""),"Incomplete",IFERROR(INDEX('Kano Matrix'!$B$5:$F$9,MATCH('Raw Responses'!P11,'Kano Matrix'!$A$5:$A$9,0),MATCH('Raw Responses'!Q11,'Kano Matrix'!$B$4:$F$4,0)),"Incomplete")) -> M | J11: =IF(OR('Raw Responses'!R11="",'Raw Responses'!S11=""),"Incomplete",IFERROR(INDEX('Kano Matrix'!$B$5:$F$9,MATCH('Raw Responses'!R11,'Kano Matrix'!$A$5:$A$9,0),MATCH('Raw Responses'!S11,'Kano Matrix'!$B$4:$F$4,0)),"Incomplete")) -> A | K11: =IF(OR('Raw Responses'!T11="",'Raw Responses'!U11=""),"Incomplete",IFERROR(INDEX('Kano Matrix'!$B$5:$F$9,MATCH('Raw Responses'!T11,'Kano Matrix'!$A$5:$A$9,0),MATCH('Raw Responses'!U11,'Kano Matrix'!$B$4:$F$4,0)),"Incomplete")) -> I
A12: ='Raw Responses'!A12 -> 2026/09/23 12:28:47 PM GMT+5 | B12: =IF(OR('Raw Responses'!B12="",'Raw Responses'!C12=""),"Incomplete",IFERROR(INDEX('Kano Matrix'!$B$5:$F$9,MATCH('Raw Responses'!B12,'Kano Matrix'!$A$5:$A$9,0),MATCH('Raw Responses'!C12,'Kano Matrix'!$B$4:$F$4,0)),"Incomplete")) -> O | C12: =IF(OR('Raw Responses'!D12="",'Raw Responses'!E12=""),"Incomplete",IFERROR(INDEX('Kano Matrix'!$B$5:$F$9,MATCH('Raw Responses'!D12,'Kano Matrix'!$A$5:$A$9,0),MATCH('Raw Responses'!E12,'Kano Matrix'!$B$4:$F$4,0)),"Incomplete")) -> O | D12: =IF(OR('Raw Responses'!F12="",'Raw Responses'!G12=""),"Incomplete",IFERROR(INDEX('Kano Matrix'!$B$5:$F$9,MATCH('Raw Responses'!F12,'Kano Matrix'!$A$5:$A$9,0),MATCH('Raw Responses'!G12,'Kano Matrix'!$B$4:$F$4,0)),"Incomplete")) -> A | E12: =IF(OR('Raw Responses'!H12="",'Raw Responses'!I12=""),"Incomplete",IFERROR(INDEX('Kano Matrix'!$B$5:$F$9,MATCH('Raw Responses'!H12,'Kano Matrix'!$A$5:$A$9,0),MATCH('Raw Responses'!I12,'Kano Matrix'!$B$4:$F$4,0)),"Incomplete")) -> A | F12: =IF(OR('Raw Responses'!J12="",'Raw Responses'!K12=""),"Incomplete",IFERROR(INDEX('Kano Matrix'!$B$5:$F$9,MATCH('Raw Responses'!J12,'Kano Matrix'!$A$5:$A$9,0),MATCH('Raw Responses'!K12,'Kano Matrix'!$B$4:$F$4,0)),"Incomplete")) -> A | G12: =IF(OR('Raw Responses'!L12="",'Raw Responses'!M12=""),"Incomplete",IFERROR(INDEX('Kano Matrix'!$B$5:$F$9,MATCH('Raw Responses'!L12,'Kano Matrix'!$A$5:$A$9,0),MATCH('Raw Responses'!M12,'Kano Matrix'!$B$4:$F$4,0)),"Incomplete")) -> R | H12: =IF(OR('Raw Responses'!N12="",'Raw Responses'!O12=""),"Incomplete",IFERROR(INDEX('Kano Matrix'!$B$5:$F$9,MATCH('Raw Responses'!N12,'Kano Matrix'!$A$5:$A$9,0),MATCH('Raw Responses'!O12,'Kano Matrix'!$B$4:$F$4,0)),"Incomplete")) -> M | I12: =IF(OR('Raw Responses'!P12="",'Raw Responses'!Q12=""),"Incomplete",IFERROR(INDEX('Kano Matrix'!$B$5:$F$9,MATCH('Raw Responses'!P12,'Kano Matrix'!$A$5:$A$9,0),MATCH('Raw Responses'!Q12,'Kano Matrix'!$B$4:$F$4,0)),"Incomplete")) -> Incomplete | J12: =IF(OR('Raw Responses'!R12="",'Raw Responses'!S12=""),"Incomplete",IFERROR(INDEX('Kano Matrix'!$B$5:$F$9,MATCH('Raw Responses'!R12,'Kano Matrix'!$A$5:$A$9,0),MATCH('Raw Responses'!S12,'Kano Matrix'!$B$4:$F$4,0)),"Incomplete")) -> Q | K12: =IF(OR('Raw Responses'!T12="",'Raw Responses'!U12=""),"Incomplete",IFERROR(INDEX('Kano Matrix'!$B$5:$F$9,MATCH('Raw Responses'!T12,'Kano Matrix'!$A$5:$A$9,0),MATCH('Raw Responses'!U12,'Kano Matrix'!$B$4:$F$4,0)),"Incomplete")) -> R
A13: ='Raw Responses'!A13 -> 2026/09/23 12:29:57 PM GMT+5 | B13: =IF(OR('Raw Responses'!B13="",'Raw Responses'!C13=""),"Incomplete",IFERROR(INDEX('Kano Matrix'!$B$5:$F$9,MATCH('Raw Responses'!B13,'Kano Matrix'!$A$5:$A$9,0),MATCH('Raw Responses'!C13,'Kano Matrix'!$B$4:$F$4,0)),"Incomplete")) -> A | C13: =IF(OR('Raw Responses'!D13="",'Raw Responses'!E13=""),"Incomplete",IFERROR(INDEX('Kano Matrix'!$B$5:$F$9,MATCH('Raw Responses'!D13,'Kano Matrix'!$A$5:$A$9,0),MATCH('Raw Responses'!E13,'Kano Matrix'!$B$4:$F$4,0)),"Incomplete")) -> I | D13: =IF(OR('Raw Responses'!F13="",'Raw Responses'!G13=""),"Incomplete",IFERROR(INDEX('Kano Matrix'!$B$5:$F$9,MATCH('Raw Responses'!F13,'Kano Matrix'!$A$5:$A$9,0),MATCH('Raw Responses'!G13,'Kano Matrix'!$B$4:$F$4,0)),"Incomplete")) -> R | E13: =IF(OR('Raw Responses'!H13="",'Raw Responses'!I13=""),"Incomplete",IFERROR(INDEX('Kano Matrix'!$B$5:$F$9,MATCH('Raw Responses'!H13,'Kano Matrix'!$A$5:$A$9,0),MATCH('Raw Responses'!I13,'Kano Matrix'!$B$4:$F$4,0)),"Incomplete")) -> I | F13: =IF(OR('Raw Responses'!J13="",'Raw Responses'!K13=""),"Incomplete",IFERROR(INDEX('Kano Matrix'!$B$5:$F$9,MATCH('Raw Responses'!J13,'Kano Matrix'!$A$5:$A$9,0),MATCH('Raw Responses'!K13,'Kano Matrix'!$B$4:$F$4,0)),"Incomplete")) -> I | G13: =IF(OR('Raw Responses'!L13="",'Raw Responses'!M13=""),"Incomplete",IFERROR(INDEX('Kano Matrix'!$B$5:$F$9,MATCH('Raw Responses'!L13,'Kano Matrix'!$A$5:$A$9,0),MATCH('Raw Responses'!M13,'Kano Matrix'!$B$4:$F$4,0)),"Incomplete")) -> I | H13: =IF(OR('Raw Responses'!N13="",'Raw Responses'!O13=""),"Incomplete",IFERROR(INDEX('Kano Matrix'!$B$5:$F$9,MATCH('Raw Responses'!N13,'Kano Matrix'!$A$5:$A$9,0),MATCH('Raw Responses'!O13,'Kano Matrix'!$B$4:$F$4,0)),"Incomplete")) -> I | I13: =IF(OR('Raw Responses'!P13="",'Raw Responses'!Q13=""),"Incomplete",IFERROR(INDEX('Kano Matrix'!$B$5:$F$9,MATCH('Raw Responses'!P13,'Kano Matrix'!$A$5:$A$9,0),MATCH('Raw Responses'!Q13,'Kano Matrix'!$B$4:$F$4,0)),"Incomplete")) -> I | J13: =IF(OR('Raw Responses'!R13="",'Raw Responses'!S13=""),"Incomplete",IFERROR(INDEX('Kano Matrix'!$B$5:$F$9,MATCH('Raw Responses'!R13,'Kano Matrix'!$A$5:$A$9,0),MATCH('Raw Responses'!S13,'Kano Matrix'!$B$4:$F$4,0)),"Incomplete")) -> I | K13: =IF(OR('Raw Responses'!T13="",'Raw Responses'!U13=""),"Incomplete",IFERROR(INDEX('Kano Matrix'!$B$5:$F$9,MATCH('Raw Responses'!T13,'Kano Matrix'!$A$5:$A$9,0),MATCH('Raw Responses'!U13,'Kano Matrix'!$B$4:$F$4,0)),"Incomplete")) -> I
A14: ='Raw Responses'!A14 -> 2026/09/23 12:29:59 PM GMT+5 | B14: =IF(OR('Raw Responses'!B14="",'Raw Responses'!C14=""),"Incomplete",IFERROR(INDEX('Kano Matrix'!$B$5:$F$9,MATCH('Raw Responses'!B14,'Kano Matrix'!$A$5:$A$9,0),MATCH('Raw Responses'!C14,'Kano Matrix'!$B$4:$F$4,0)),"Incomplete")) -> I | C14: =IF(OR('Raw Responses'!D14="",'Raw Responses'!E14=""),"Incomplete",IFERROR(INDEX('Kano Matrix'!$B$5:$F$9,MATCH('Raw Responses'!D14,'Kano Matrix'!$A$5:$A$9,0),MATCH('Raw Responses'!E14,'Kano Matrix'!$B$4:$F$4,0)),"Incomplete")) -> Q | D14: =IF(OR('Raw Responses'!F14="",'Raw Responses'!G14=""),"Incomplete",IFERROR(INDEX('Kano Matrix'!$B$5:$F$9,MATCH('Raw Responses'!F14,'Kano Matrix'!$A$5:$A$9,0),MATCH('Raw Responses'!G14,'Kano Matrix'!$B$4:$F$4,0)),"Incomplete")) -> I | E14: =IF(OR('Raw Responses'!H14="",'Raw Responses'!I14=""),"Incomplete",IFERROR(INDEX('Kano Matrix'!$B$5:$F$9,MATCH('Raw Responses'!H14,'Kano Matrix'!$A$5:$A$9,0),MATCH('Raw Responses'!I14,'Kano Matrix'!$B$4:$F$4,0)),"Incomplete")) -> R | F14: =IF(OR('Raw Responses'!J14="",'Raw Responses'!K14=""),"Incomplete",IFERROR(INDEX('Kano Matrix'!$B$5:$F$9,MATCH('Raw Responses'!J14,'Kano Matrix'!$A$5:$A$9,0),MATCH('Raw Responses'!K14,'Kano Matrix'!$B$4:$F$4,0)),"Incomplete")) -> A | G14: =IF(OR('Raw Responses'!L14="",'Raw Responses'!M14=""),"Incomplete",IFERROR(INDEX('Kano Matrix'!$B$5:$F$9,MATCH('Raw Responses'!L14,'Kano Matrix'!$A$5:$A$9,0),MATCH('Raw Responses'!M14,'Kano Matrix'!$B$4:$F$4,0)),"Incomplete")) -> R | H14: =IF(OR('Raw Responses'!N14="",'Raw Responses'!O14=""),"Incomplete",IFERROR(INDEX('Kano Matrix'!$B$5:$F$9,MATCH('Raw Responses'!N14,'Kano Matrix'!$A$5:$A$9,0),MATCH('Raw Responses'!O14,'Kano Matrix'!$B$4:$F$4,0)),"Incomplete")) -> M | I14: =IF(OR('Raw Responses'!P14="",'Raw Responses'!Q14=""),"Incomplete",IFERROR(INDEX('Kano Matrix'!$B$5:$F$9,MATCH('Raw Responses'!P14,'Kano Matrix'!$A$5:$A$9,0),MATCH('Raw Responses'!Q14,'Kano Matrix'!$B$4:$F$4,0)),"Incomplete")) -> R | J14: =IF(OR('Raw Responses'!R14="",'Raw Responses'!S14=""),"Incomplete",IFERROR(INDEX('Kano Matrix'!$B$5:$F$9,MATCH('Raw Responses'!R14,'Kano Matrix'!$A$5:$A$9,0),MATCH('Raw Responses'!S14,'Kano Matrix'!$B$4:$F$4,0)),"Incomplete")) -> Q | K14: =IF(OR('Raw Responses'!T14="",'Raw Responses'!U14=""),"Incomplete",IFERROR(INDEX('Kano Matrix'!$B$5:$F$9,MATCH('Raw Responses'!T14,'Kano Matrix'!$A$5:$A$9,0),MATCH('Raw Responses'!U14,'Kano Matrix'!$B$4:$F$4,0)),"Incomplete")) -> I
A15: ='Raw Responses'!A15 -> 2026/09/23 12:32:18 PM GMT+5 | B15: =IF(OR('Raw Responses'!B15="",'Raw Responses'!C15=""),"Incomplete",IFERROR(INDEX('Kano Matrix'!$B$5:$F$9,MATCH('Raw Responses'!B15,'Kano Matrix'!$A$5:$A$9,0),MATCH('Raw Responses'!C15,'Kano Matrix'!$B$4:$F$4,0)),"Incomplete")) -> O | C15: =IF(OR('Raw Responses'!D15="",'Raw Responses'!E15=""),"Incomplete",IFERROR(INDEX('Kano Matrix'!$B$5:$F$9,MATCH('Raw Responses'!D15,'Kano Matrix'!$A$5:$A$9,0),MATCH('Raw Responses'!E15,'Kano Matrix'!$B$4:$F$4,0)),"Incomplete")) -> O | D15: =IF(OR('Raw Responses'!F15="",'Raw Responses'!G15=""),"Incomplete",IFERROR(INDEX('Kano Matrix'!$B$5:$F$9,MATCH('Raw Responses'!F15,'Kano Matrix'!$A$5:$A$9,0),MATCH('Raw Responses'!G15,'Kano Matrix'!$B$4:$F$4,0)),"Incomplete")) -> O | E15: =IF(OR('Raw Responses'!H15="",'Raw Responses'!I15=""),"Incomplete",IFERROR(INDEX('Kano Matrix'!$B$5:$F$9,MATCH('Raw Responses'!H15,'Kano Matrix'!$A$5:$A$9,0),MATCH('Raw Responses'!I15,'Kano Matrix'!$B$4:$F$4,0)),"Incomplete")) -> O | F15: =IF(OR('Raw Responses'!J15="",'Raw Responses'!K15=""),"Incomplete",IFERROR(INDEX('Kano Matrix'!$B$5:$F$9,MATCH('Raw Responses'!J15,'Kano Matrix'!$A$5:$A$9,0),MATCH('Raw Responses'!K15,'Kano Matrix'!$B$4:$F$4,0)),"Incomplete")) -> O | G15: =IF(OR('Raw Responses'!L15="",'Raw Responses'!M15=""),"Incomplete",IFERROR(INDEX('Kano Matrix'!$B$5:$F$9,MATCH('Raw Responses'!L15,'Kano Matrix'!$A$5:$A$9,0),MATCH('Raw Responses'!M15,'Kano Matrix'!$B$4:$F$4,0)),"Incomplete")) -> A | H15: =IF(OR('Raw Responses'!N15="",'Raw Responses'!O15=""),"Incomplete",IFERROR(INDEX('Kano Matrix'!$B$5:$F$9,MATCH('Raw Responses'!N15,'Kano Matrix'!$A$5:$A$9,0),MATCH('Raw Responses'!O15,'Kano Matrix'!$B$4:$F$4,0)),"Incomplete")) -> O | I15: =IF(OR('Raw Responses'!P15="",'Raw Responses'!Q15=""),"Incomplete",IFERROR(INDEX('Kano Matrix'!$B$5:$F$9,MATCH('Raw Responses'!P15,'Kano Matrix'!$A$5:$A$9,0),MATCH('Raw Responses'!Q15,'Kano Matrix'!$B$4:$F$4,0)),"Incomplete")) -> O | J15: =IF(OR('Raw Responses'!R15="",'Raw Responses'!S15=""),"Incomplete",IFERROR(INDEX('Kano Matrix'!$B$5:$F$9,MATCH('Raw Responses'!R15,'Kano Matrix'!$A$5:$A$9,0),MATCH('Raw Responses'!S15,'Kano Matrix'!$B$4:$F$4,0)),"Incomplete")) -> O | K15: =IF(OR('Raw Responses'!T15="",'Raw Responses'!U15=""),"Incomplete",IFERROR(INDEX('Kano Matrix'!$B$5:$F$9,MATCH('Raw Responses'!T15,'Kano Matrix'!$A$5:$A$9,0),MATCH('Raw Responses'!U15,'Kano Matrix'!$B$4:$F$4,0)),"Incomplete")) -> O
A16: ='Raw Responses'!A16 -> 2026/09/23 12:33:43 PM GMT+5 | B16: =IF(OR('Raw Responses'!B16="",'Raw Responses'!C16=""),"Incomplete",IFERROR(INDEX('Kano Matrix'!$B$5:$F$9,MATCH('Raw Responses'!B16,'Kano Matrix'!$A$5:$A$9,0),MATCH('Raw Responses'!C16,'Kano Matrix'!$B$4:$F$4,0)),"Incomplete")) -> O | C16: =IF(OR('Raw Responses'!D16="",'Raw Responses'!E16=""),"Incomplete",IFERROR(INDEX('Kano Matrix'!$B$5:$F$9,MATCH('Raw Responses'!D16,'Kano Matrix'!$A$5:$A$9,0),MATCH('Raw Responses'!E16,'Kano Matrix'!$B$4:$F$4,0)),"Incomplete")) -> A | D16: =IF(OR('Raw Responses'!F16="",'Raw Responses'!G16=""),"Incomplete",IFERROR(INDEX('Kano Matrix'!$B$5:$F$9,MATCH('Raw Responses'!F16,'Kano Matrix'!$A$5:$A$9,0),MATCH('Raw Responses'!G16,'Kano Matrix'!$B$4:$F$4,0)),"Incomplete")) -> I | E16: =IF(OR('Raw Responses'!H16="",'Raw Responses'!I16=""),"Incomplete",IFERROR(INDEX('Kano Matrix'!$B$5:$F$9,MATCH('Raw Responses'!H16,'Kano Matrix'!$A$5:$A$9,0),MATCH('Raw Responses'!I16,'Kano Matrix'!$B$4:$F$4,0)),"Incomplete")) -> I | F16: =IF(OR('Raw Responses'!J16="",'Raw Responses'!K16=""),"Incomplete",IFERROR(INDEX('Kano Matrix'!$B$5:$F$9,MATCH('Raw Responses'!J16,'Kano Matrix'!$A$5:$A$9,0),MATCH('Raw Responses'!K16,'Kano Matrix'!$B$4:$F$4,0)),"Incomplete")) -> M | G16: =IF(OR('Raw Responses'!L16="",'Raw Responses'!M16=""),"Incomplete",IFERROR(INDEX('Kano Matrix'!$B$5:$F$9,MATCH('Raw Responses'!L16,'Kano Matrix'!$A$5:$A$9,0),MATCH('Raw Responses'!M16,'Kano Matrix'!$B$4:$F$4,0)),"Incomplete")) -> A | H16: =IF(OR('Raw Responses'!N16="",'Raw Responses'!O16=""),"Incomplete",IFERROR(INDEX('Kano Matrix'!$B$5:$F$9,MATCH('Raw Responses'!N16,'Kano Matrix'!$A$5:$A$9,0),MATCH('Raw Responses'!O16,'Kano Matrix'!$B$4:$F$4,0)),"Incomplete")) -> I | I16: =IF(OR('Raw Responses'!P16="",'Raw Responses'!Q16=""),"Incomplete",IFERROR(INDEX('Kano Matrix'!$B$5:$F$9,MATCH('Raw Responses'!P16,'Kano Matrix'!$A$5:$A$9,0),MATCH('Raw Responses'!Q16,'Kano Matrix'!$B$4:$F$4,0)),"Incomplete")) -> A | J16: =IF(OR('Raw Responses'!R16="",'Raw Responses'!S16=""),"Incomplete",IFERROR(INDEX('Kano Matrix'!$B$5:$F$9,MATCH('Raw Responses'!R16,'Kano Matrix'!$A$5:$A$9,0),MATCH('Raw Responses'!S16,'Kano Matrix'!$B$4:$F$4,0)),"Incomplete")) -> I | K16: =IF(OR('Raw Responses'!T16="",'Raw Responses'!U16=""),"Incomplete",IFERROR(INDEX('Kano Matrix'!$B$5:$F$9,MATCH('Raw Responses'!T16,'Kano Matrix'!$A$5:$A$9,0),MATCH('Raw Responses'!U16,'Kano Matrix'!$B$4:$F$4,0)),"Incomplete")) -> A
... A44: ='Raw Responses'!A44 -> 2026/09/23 7:51:54 PM GMT+5 | B44: =IF(OR('Raw Responses'!B44="",'Raw Responses'!C44=""),"Incomplete",IFERROR(INDEX('Kano Matrix'!$B$5:$F$9,MATCH('Raw Responses'!B44,'Kano Matrix'!$A$5:$A$9,0),MATCH('Raw Responses'!C44,'Kano Matrix'!$B$4:$F$4,0)),"Incomplete")) -> O | C44: =IF(OR('Raw Responses'!D44="",'Raw Responses'!E44=""),"Incomplete",IFERROR(INDEX('Kano Matrix'!$B$5:$F$9,MATCH('Raw Responses'!D44,'Kano Matrix'!$A$5:$A$9,0),MATCH('Raw Responses'!E44,'Kano Matrix'!$B$4:$F$4,0)),"Incomplete")) -> O | D44: =IF(OR('Raw Responses'!F44="",'Raw Responses'!G44=""),"Incomplete",IFERROR(INDEX('Kano Matrix'!$B$5:$F$9,MATCH('Raw Responses'!F44,'Kano Matrix'!$A$5:$A$9,0),MATCH('Raw Responses'!G44,'Kano Matrix'!$B$4:$F$4,0)),"Incomplete")) -> M | E44: =IF(OR('Raw Responses'!H44="",'Raw Responses'!I44=""),"Incomplete",IFERROR(INDEX('Kano Matrix'!$B$5:$F$9,MATCH('Raw Responses'!H44,'Kano Matrix'!$A$5:$A$9,0),MATCH('Raw Responses'!I44,'Kano Matrix'!$B$4:$F$4,0)),"Incomplete")) -> O | F44: =IF(OR('Raw Responses'!J44="",'Raw Responses'!K44=""),"Incomplete",IFERROR(INDEX('Kano Matrix'!$B$5:$F$9,MATCH('Raw Responses'!J44,'Kano Matrix'!$A$5:$A$9,0),MATCH('Raw Responses'!K44,'Kano Matrix'!$B$4:$F$4,0)),"Incomplete")) -> O | G44: =IF(OR('Raw Responses'!L44="",'Raw Responses'!M44=""),"Incomplete",IFERROR(INDEX('Kano Matrix'!$B$5:$F$9,MATCH('Raw Responses'!L44,'Kano Matrix'!$A$5:$A$9,0),MATCH('Raw Responses'!M44,'Kano Matrix'!$B$4:$F$4,0)),"Incomplete")) -> I | H44: =IF(OR('Raw Responses'!N44="",'Raw Responses'!O44=""),"Incomplete",IFERROR(INDEX('Kano Matrix'!$B$5:$F$9,MATCH('Raw Responses'!N44,'Kano Matrix'!$A$5:$A$9,0),MATCH('Raw Responses'!O44,'Kano Matrix'!$B$4:$F$4,0)),"Incomplete")) -> M | I44: =IF(OR('Raw Responses'!P44="",'Raw Responses'!Q44=""),"Incomplete",IFERROR(INDEX('Kano Matrix'!$B$5:$F$9,MATCH('Raw Responses'!P44,'Kano Matrix'!$A$5:$A$9,0),MATCH('Raw Responses'!Q44,'Kano Matrix'!$B$4:$F$4,0)),"Incomplete")) -> I | J44: =IF(OR('Raw Responses'!R44="",'Raw Responses'!S44=""),"Incomplete",IFERROR(INDEX('Kano Matrix'!$B$5:$F$9,MATCH('Raw Responses'!R44,'Kano Matrix'!$A$5:$A$9,0),MATCH('Raw Responses'!S44,'Kano Matrix'!$B$4:$F$4,0)),"Incomplete")) -> M | K44: =IF(OR('Raw Responses'!T44="",'Raw Responses'!U44=""),"Incomplete",IFERROR(INDEX('Kano Matrix'!$B$5:$F$9,MATCH('Raw Responses'!T44,'Kano Matrix'!$A$5:$A$9,0),MATCH('Raw Responses'!U44,'Kano Matrix'!$B$4:$F$4,0)),"Incomplete")) -> M

Sheet Summary
A1: Kano Summary — University Course Registration System
A2: n = 40 respondents. Dominant category uses tie-break priority M > O > A > I > R > Q.
A4: Feature | B4: M | C4: O | D4: A | E4: I | F4: R | G4: Q | H4: Incomplete | I4: Total | J4: Dominant
A5: Course search (code/title/dept) | B5: =COUNTIF(Classification!$B$5:$B$44,"M") -> 1 | C5: =COUNTIF(Classification!$B$5:$B$44,"O") -> 11 | D5: =COUNTIF(Classification!$B$5:$B$44,"A") -> 15 | E5: =COUNTIF(Classification!$B$5:$B$44,"I") -> 8 | F5: =COUNTIF(Classification!$B$5:$B$44,"R") -> 0 | G5: =COUNTIF(Classification!$B$5:$B$44,"Q") -> 4 | H5: =COUNTIF(Classification!$B$5:$B$44,"Incomplete") -> 1 | I5: =SUM(B5:H5) -> 40 | J5: =INDEX($B$4:$G$4,MATCH(MAX(B5:G5),B5:G5,0)) -> A
A6: Remaining seats display | B6: =COUNTIF(Classification!$C$5:$C$44,"M") -> 4 | C6: =COUNTIF(Classification!$C$5:$C$44,"O") -> 9 | D6: =COUNTIF(Classification!$C$5:$C$44,"A") -> 12 | E6: =COUNTIF(Classification!$C$5:$C$44,"I") -> 9 | F6: =COUNTIF(Classification!$C$5:$C$44,"R") -> 0 | G6: =COUNTIF(Classification!$C$5:$C$44,"Q") -> 4 | H6: =COUNTIF(Classification!$C$5:$C$44,"Incomplete") -> 2 | I6: =SUM(B6:H6) -> 40 | J6: =INDEX($B$4:$G$4,MATCH(MAX(B6:G6),B6:G6,0)) -> A
A7: Registration confirmation | B7: =COUNTIF(Classification!$D$5:$D$44,"M") -> 5 | C7: =COUNTIF(Classification!$D$5:$D$44,"O") -> 12 | D7: =COUNTIF(Classification!$D$5:$D$44,"A") -> 5 | E7: =COUNTIF(Classification!$D$5:$D$44,"I") -> 10 | F7: =COUNTIF(Classification!$D$5:$D$44,"R") -> 2 | G7: =COUNTIF(Classification!$D$5:$D$44,"Q") -> 4 | H7: =COUNTIF(Classification!$D$5:$D$44,"Incomplete") -> 2 | I7: =SUM(B7:H7) -> 40 | J7: =INDEX($B$4:$G$4,MATCH(MAX(B7:G7),B7:G7,0)) -> O
A8: SMS/email notification | B8: =COUNTIF(Classification!$E$5:$E$44,"M") -> 2 | C8: =COUNTIF(Classification!$E$5:$E$44,"O") -> 9 | D8: =COUNTIF(Classification!$E$5:$E$44,"A") -> 9 | E8: =COUNTIF(Classification!$E$5:$E$44,"I") -> 13 | F8: =COUNTIF(Classification!$E$5:$E$44,"R") -> 1 | G8: =COUNTIF(Classification!$E$5:$E$44,"Q") -> 4 | H8: =COUNTIF(Classification!$E$5:$E$44,"Incomplete") -> 2 | I8: =SUM(B8:H8) -> 40 | J8: =INDEX($B$4:$G$4,MATCH(MAX(B8:G8),B8:G8,0)) -> I
A9: Automatic course recommendations | B9: =COUNTIF(Classification!$F$5:$F$44,"M") -> 1 | C9: =COUNTIF(Classification!$F$5:$F$44,"O") -> 8 | D9: =COUNTIF(Classification!$F$5:$F$44,"A") -> 8 | E9: =COUNTIF(Classification!$F$5:$F$44,"I") -> 12 | F9: =COUNTIF(Classification!$F$5:$F$44,"R") -> 3 | G9: =COUNTIF(Classification!$F$5:$F$44,"Q") -> 4 | H9: =COUNTIF(Classification!$F$5:$F$44,"Incomplete") -> 4 | I9: =SUM(B9:H9) -> 40 | J9: =INDEX($B$4:$G$4,MATCH(MAX(B9:G9),B9:G9,0)) -> I
A10: Dark mode | B10: =COUNTIF(Classification!$G$5:$G$44,"M") -> 1 | C10: =COUNTIF(Classification!$G$5:$G$44,"O") -> 8 | D10: =COUNTIF(Classification!$G$5:$G$44,"A") -> 6 | E10: =COUNTIF(Classification!$G$5:$G$44,"I") -> 13 | F10: =COUNTIF(Classification!$G$5:$G$44,"R") -> 5 | G10: =COUNTIF(Classification!$G$5:$G$44,"Q") -> 6 | H10: =COUNTIF(Classification!$G$5:$G$44,"Incomplete") -> 1 | I10: =SUM(B10:H10) -> 40 | J10: =INDEX($B$4:$G$4,MATCH(MAX(B10:G10),B10:G10,0)) -> I
A11: Download timetable as PDF | B11: =COUNTIF(Classification!$H$5:$H$44,"M") -> 5 | C11: =COUNTIF(Classification!$H$5:$H$44,"O") -> 11 | D11: =COUNTIF(Classification!$H$5:$H$44,"A") -> 8 | E11: =COUNTIF(Classification!$H$5:$H$44,"I") -> 7 | F11: =COUNTIF(Classification!$H$5:$H$44,"R") -> 1 | G11: =COUNTIF(Classification!$H$5:$H$44,"Q") -> 6 | H11: =COUNTIF(Classification!$H$5:$H$44,"Incomplete") -> 2 | I11: =SUM(B11:H11) -> 40 | J11: =INDEX($B$4:$G$4,MATCH(MAX(B11:G11),B11:G11,0)) -> O
A12: Remember selected courses | B12: =COUNTIF(Classification!$I$5:$I$44,"M") -> 3 | C12: =COUNTIF(Classification!$I$5:$I$44,"O") -> 8 | D12: =COUNTIF(Classification!$I$5:$I$44,"A") -> 9 | E12: =COUNTIF(Classification!$I$5:$I$44,"I") -> 10 | F12: =COUNTIF(Classification!$I$5:$I$44,"R") -> 3 | G12: =COUNTIF(Classification!$I$5:$I$44,"Q") -> 4 | H12: =COUNTIF(Classification!$I$5:$I$44,"Incomplete") -> 3 | I12: =SUM(B12:H12) -> 40 | J12: =INDEX($B$4:$G$4,MATCH(MAX(B12:G12),B12:G12,0)) -> I
A13: Data preservation (network issue) | B13: =COUNTIF(Classification!$J$5:$J$44,"M") -> 3 | C13: =COUNTIF(Classification!$J$5:$J$44,"O") -> 8 | D13: =COUNTIF(Classification!$J$5:$J$44,"A") -> 5 | E13: =COUNTIF(Classification!$J$5:$J$44,"I") -> 10 | F13: =COUNTIF(Classification!$J$5:$J$44,"R") -> 3 | G13: =COUNTIF(Classification!$J$5:$J$44,"Q") -> 8 | H13: =COUNTIF(Classification!$J$5:$J$44,"Incomplete") -> 3 | I13: =SUM(B13:H13) -> 40 | J13: =INDEX($B$4:$G$4,MATCH(MAX(B13:G13),B13:G13,0)) -> I
A14: Fast response during peak periods | B14: =COUNTIF(Classification!$K$5:$K$44,"M") -> 5 | C14: =COUNTIF(Classification!$K$5:$K$44,"O") -> 12 | D14: =COUNTIF(Classification!$K$5:$K$44,"A") -> 7 | E14: =COUNTIF(Classification!$K$5:$K$44,"I") -> 9 | F14: =COUNTIF(Classification!$K$5:$K$44,"R") -> 1 | G14: =COUNTIF(Classification!$K$5:$K$44,"Q") -> 5 | H14: =COUNTIF(Classification!$K$5:$K$44,"Incomplete") -> 1 | I14: =SUM(B14:H14) -> 40 | J14: =INDEX($B$4:$G$4,MATCH(MAX(B14:G14),B14:G14,0)) -> O
